Workbook

Sheet 实验总览
B2: 荧光酶活性筛选与批次质控
B3: 荧光酶活分析 3 个独立批次 · 每剂量每批次 8 个技术重复 模拟数据
B5: 孔位读数 / 个 | F5: 独立批次 / 个 | J5: 每剂量技术重复 / 批次 | N5: 剂量水平 / 档
B6: =COUNTA('原始读数'!B8:B295) -> 288 | F6: =COUNTA('板内质控'!A8:A10) -> 3 | J6: =COUNT('原始读数'!F24:F31) -> 8 | N6: =COUNT('剂量响应'!A8:A17) -> 10
B9: 01 剂量升高时，相对酶活性如何变化
B28: 02 对照稳定性与组内重复差异
B44: 关键读数与复核事项
B45: 浓度 / µM | F45: 平均活性 | J45: 批次 SD | N45: 复核标记
B46: ='剂量响应'!A8 -> 0.01 | F46: ='剂量响应'!E8 -> 0.98130816 | J46: ='剂量响应'!F8 -> 0.0096596056 | N46: =IF('剂量响应'!H8>'板内质控'!$L$8,"复核 CV","正常") -> 正常
B47: ='剂量响应'!A13 -> 3 | F47: ='剂量响应'!E13 -> 0.6216414 | J47: ='剂量响应'!F13 -> 0.059753385 | N47: =IF('剂量响应'!H13>'板内质控'!$L$8,"复核 CV","正常") -> 复核 CV
B48: ='剂量响应'!A14 -> 10 | F48: ='剂量响应'!E14 -> 0.30237952 | J48: ='剂量响应'!F14 -> 0.014671842 | N48: =IF('剂量响应'!H14>'板内质控'!$L$8,"复核 CV","正常") -> 正常
B49: ='剂量响应'!A17 -> 100 | F49: ='剂量响应'!E17 -> 0.034360986 | J49: ='剂量响应'!F17 -> 0.0022042539 | N49: =IF('剂量响应'!H17>'板内质控'!$L$8,"复核 CV","正常") -> 正常
B51: 50% 抑制区间 / µM
B52: =IF(SUMPRODUCT(--('剂量响应'!G9:G17<'剂量响应'!G8:G16))>0,"响应有回升，逐段复核",IF(COUNTIFS('剂量响应'!G8:G17,"<0.5")=0,"低于最低测试浓度",IF(COUNTIFS('剂量响应'!G8:G17,"<0.5")=10,"高于最高测试浓度",INDEX('剂量响应'!A8:A17,COUNTIFS('剂量响应'!G8:G17,"<0.5"))&" 至 "&INDEX('剂量响应'!A8:A17,COUNTIFS('剂量响应'!G8:G17,"<0.5")+1)))) -> 响应有回升，逐段复核
B54: 模拟读数用于展示分析结构；偏差记录与原始孔位保留，可在后续工作表核对。

Sheet 剂量响应
A2: 剂量响应与批次统计
A3: 批次均值先分别归一化，再计算跨批次均值和样本 SD；n = 3
A7: 浓度 / µM | B7: P1 活性 | C7: P2 活性 | D7: P3 活性 | E7: 批次均值 | F7: 批次 SD | G7: 平均抑制率 | H7: 最大组内 CV
A8: 0.01 | B8: =(AVERAGE('原始读数'!F24:F31)-'板内质控'!B8)/'板内质控'!G8 -> 0.98955949 | C8: =(AVERAGE('原始读数'!F120:F127)-'板内质控'!B9)/'板内质控'!G9 -> 0.98368209 | D8: =(AVERAGE('原始读数'!F216:F223)-'板内质控'!B10)/'板内质控'!G10 -> 0.97068291 | E8: =AVERAGE(B8:D8) -> 0.98130816 | F8: =STDEV(B8:D8) -> 0.0096596056 | G8: =1-E8 -> 0.018691839 | H8: =MAX(STDEV('原始读数'!F24:F31)/(AVERAGE('原始读数'!F24:F31)-'板内质控'!B8),STDEV('原始读数'!F120:F127)/(AVERAGE('原始读数'!F120:F127)-'板内质控'!B9),STDEV('原始读数'!F216:F223)/(AVERAGE('原始读数'!F216:F223)-'板内质控'!B10)) -> 0.048744789
A9: 0.03 | B9: =(AVERAGE('原始读数'!F32:F39)-'板内质控'!B8)/'板内质控'!G8 -> 0.9818971 | C9: =(AVERAGE('原始读数'!F128:F135)-'板内质控'!B9)/'板内质控'!G9 -> 1.008609 | D9: =(AVERAGE('原始读数'!F224:F231)-'板内质控'!B10)/'板内质控'!G10 -> 0.96323143 | E9: =AVERAGE(B9:D9) -> 0.98457918 | F9: =STDEV(B9:D9) -> 0.02280738 | G9: =1-E9 -> 0.015420819 | H9: =MAX(STDEV('原始读数'!F32:F39)/(AVERAGE('原始读数'!F32:F39)-'板内质控'!B8),STDEV('原始读数'!F128:F135)/(AVERAGE('原始读数'!F128:F135)-'板内质控'!B9),STDEV('原始读数'!F224:F231)/(AVERAGE('原始读数'!F224:F231)-'板内质控'!B10)) -> 0.031558545
A10: 0.1 | B10: =(AVERAGE('原始读数'!F40:F47)-'板内质控'!B8)/'板内质控'!G8 -> 0.98935769 | C10: =(AVERAGE('原始读数'!F136:F143)-'板内质控'!B9)/'板内质控'!G9 -> 0.98607417 | D10: =(AVERAGE('原始读数'!F232:F239)-'板内质控'!B10)/'板内质控'!G10 -> 0.96900412 | E10: =AVERAGE(B10:D10) -> 0.98147866 | F10: =STDEV(B10:D10) -> 0.010927304 | G10: =1-E10 -> 0.018521339 | H10: =MAX(STDEV('原始读数'!F40:F47)/(AVERAGE('原始读数'!F40:F47)-'板内质控'!B8),STDEV('原始读数'!F136:F143)/(AVERAGE('原始读数'!F136:F143)-'板内质控'!B9),STDEV('原始读数'!F232:F239)/(AVERAGE('原始读数'!F232:F239)-'板内质控'!B10)) -> 0.044403501
A11: 0.3 | B11: =(AVERAGE('原始读数'!F48:F55)-'板内质控'!B8)/'板内质控'!G8 -> 0.95275614 | C11: =(AVERAGE('原始读数'!F144:F151)-'板内质控'!B9)/'板内质控'!G9 -> 0.94355026 | D11: =(AVERAGE('原始读数'!F240:F247)-'板内质控'!B10)/'板内质控'!G10 -> 0.94437954 | E11: =AVERAGE(B11:D11) -> 0.94689531 | F11: =STDEV(B11:D11) -> 0.0050925301 | G11: =1-E11 -> 0.053104686 | H11: =MAX(STDEV('原始读数'!F48:F55)/(AVERAGE('原始读数'!F48:F55)-'板内质控'!B8),STDEV('原始读数'!F144:F151)/(AVERAGE('原始读数'!F144:F151)-'板内质控'!B9),STDEV('原始读数'!F240:F247)/(AVERAGE('原始读数'!F240:F247)-'板内质控'!B10)) -> 0.042690499
A12: 1 | B12: =(AVERAGE('原始读数'!F56:F63)-'板内质控'!B8)/'板内质控'!G8 -> 0.83064876 | C12: =(AVERAGE('原始读数'!F152:F159)-'板内质控'!B9)/'板内质控'!G9 -> 0.85294713 | D12: =(AVERAGE('原始读数'!F248:F255)-'板内质控'!B10)/'板内质控'!G10 -> 0.82937509 | E12: =AVERAGE(B12:D12) -> 0.83765699 | F12: =STDEV(B12:D12) -> 0.01325695 | G12: =1-E12 -> 0.16234301 | H12: =MAX(STDEV('原始读数'!F56:F63)/(AVERAGE('原始读数'!F56:F63)-'板内质控'!B8),STDEV('原始读数'!F152:F159)/(AVERAGE('原始读数'!F152:F159)-'板内质控'!B9),STDEV('原始读数'!F248:F255)/(AVERAGE('原始读数'!F248:F255)-'板内质控'!B10)) -> 0.03702051
A13: 3 | B13: =(AVERAGE('原始读数'!F64:F71)-'板内质控'!B8)/'板内质控'!G8 -> 0.58261847 | C13: =(AVERAGE('原始读数'!F160:F167)-'板内质控'!B9)/'板内质控'!G9 -> 0.69043141 | D13: =(AVERAGE('原始读数'!F256:F263)-'板内质控'!B10)/'板内质控'!G10 -> 0.59187431 | E13: =AVERAGE(B13:D13) -> 0.6216414 | F13: =STDEV(B13:D13) -> 0.059753385 | G13: =1-E13 -> 0.3783586 | H13: =MAX(STDEV('原始读数'!F64:F71)/(AVERAGE('原始读数'!F64:F71)-'板内质控'!B8),STDEV('原始读数'!F160:F167)/(AVERAGE('原始读数'!F160:F167)-'板内质控'!B9),STDEV('原始读数'!F256:F263)/(AVERAGE('原始读数'!F256:F263)-'板内质控'!B10)) -> 0.19078832
A14: 10 | B14: =(AVERAGE('原始读数'!F72:F79)-'板内质控'!B8)/'板内质控'!G8 -> 0.29012344 | C14: =(AVERAGE('原始读数'!F168:F175)-'板内质控'!B9)/'板内质控'!G9 -> 0.31863694 | D14: =(AVERAGE('原始读数'!F264:F271)-'板内质控'!B10)/'板内质控'!G10 -> 0.29837818 | E14: =AVERAGE(B14:D14) -> 0.30237952 | F14: =STDEV(B14:D14) -> 0.014671842 | G14: =1-E14 -> 0.69762048 | H14: =MAX(STDEV('原始读数'!F72:F79)/(AVERAGE('原始读数'!F72:F79)-'板内质控'!B8),STDEV('原始读数'!F168:F175)/(AVERAGE('原始读数'!F168:F175)-'板内质控'!B9),STDEV('原始读数'!F264:F271)/(AVERAGE('原始读数'!F264:F271)-'板内质控'!B10)) -> 0.03555935
A15: 30 | B15: =(AVERAGE('原始读数'!F80:F87)-'板内质控'!B8)/'板内质控'!G8 -> 0.11007797 | C15: =(AVERAGE('原始读数'!F176:F183)-'板内质控'!B9)/'板内质控'!G9 -> 0.12655412 | D15: =(AVERAGE('原始读数'!F272:F279)-'板内质控'!B10)/'板内质控'!G10 -> 0.11311854 | E15: =AVERAGE(B15:D15) -> 0.11658354 | F15: =STDEV(B15:D15) -> 0.0087675896 | G15: =1-E15 -> 0.88341646 | H15: =MAX(STDEV('原始读数'!F80:F87)/(AVERAGE('原始读数'!F80:F87)-'板内质控'!B8),STDEV('原始读数'!F176:F183)/(AVERAGE('原始读数'!F176:F183)-'板内质控'!B9),STDEV('原始读数'!F272:F279)/(AVERAGE('原始读数'!F272:F279)-'板内质控'!B10)) -> 0.048273185
A16: 60 | B16: =(AVERAGE('原始读数'!F88:F95)-'板内质控'!B8)/'板内质控'!G8 -> 0.053991307 | C16: =(AVERAGE('原始读数'!F184:F191)-'板内质控'!B9)/'板内质控'!G9 -> 0.063146328 | D16: =(AVERAGE('原始读数'!F280:F287)-'板内质控'!B10)/'板内质控'!G10 -> 0.057316846 | E16: =AVERAGE(B16:D16) -> 0.058151494 | F16: =STDEV(B16:D16) -> 0.004634229 | G16: =1-E16 -> 0.94184851 | H16: =MAX(STDEV('原始读数'!F88:F95)/(AVERAGE('原始读数'!F88:F95)-'板内质控'!B8),STDEV('原始读数'!F184:F191)/(AVERAGE('原始读数'!F184:F191)-'板内质控'!B9),STDEV('原始读数'!F280:F287)/(AVERAGE('原始读数'!F280:F287)-'板内质控'!B10)) -> 0.029495195
A17: 100 | B17: =(AVERAGE('原始读数'!F96:F103)-'板内质控'!B8)/'板内质控'!G8 -> 0.032588156 | C17: =(AVERAGE('原始读数'!F192:F199)-'板内质控'!B9)/'板内质控'!G9 -> 0.036829027 | D17: =(AVERAGE('原始读数'!F288:F295)-'板内质控'!B10)/'板内质控'!G10 -> 0.033665776 | E17: =AVERAGE(B17:D17) -> 0.034360986 | F17: =STDEV(B17:D17) -> 0.0022042539 | G17: =1-E17 -> 0.96563901 | H17: =MAX(STDEV('原始读数'!F96:F103)/(AVERAGE('原始读数'!F96:F103)-'板内质控'!B8),STDEV('原始读数'!F192:F199)/(AVERAGE('原始读数'!F192:F199)-'板内质控'!B9),STDEV('原始读数'!F288:F295)/(AVERAGE('原始读数'!F288:F295)-'板内质控'!B10)) -> 0.032476685
A20: 统计口径
A22: 相对活性 =（样品均值 − 本板空白均值）÷（本板溶剂对照均值 − 本板空白均值）。
A24: 跨批次离散程度使用 3 个独立批次均值的样本标准差。技术重复仅用于评价板内测量稳定性。
A26: 曲线连接实测浓度点，横轴使用对数刻度。50% 抑制浓度仅报告相邻剂量区间。
A28: 方法参考：NIH Assay Guidance Manual / Basic Guidelines for Reporting Non-Clinical Data
A29: https://www.ncbi.nlm.nih.gov/books/NBK550206/

Sheet 板内质控
A2: 板内质控与孔位分布
A3: 每板 96 孔；第 1 列空白，第 2 列溶剂对照，第 3–12 列为十档浓度
A7: 批次 | B7: 空白均值 | C7: 对照均值 | D7: 对照 SD | E7: 对照 CV | F7: 空白 SD | G7: 信号窗口
A8: P1 | B8: =AVERAGE('原始读数'!F8:F15) -> 147.35 | C8: =AVERAGE('原始读数'!F16:F23) -> 12907.737 | D8: =STDEV('原始读数'!F16:F23) -> 480.9416 | E8: =D8/C8 -> 0.037259946 | F8: =STDEV('原始读数'!F8:F15) -> 5.7201399 | G8: =C8-B8 -> 12760.388 | I8: 技术重复 CV 阈值 | L8: 0.15
A9: P2 | B9: =AVERAGE('原始读数'!F104:F111) -> 170.275 | C9: =AVERAGE('原始读数'!F112:F119) -> 14321.138 | D9: =STDEV('原始读数'!F112:F119) -> 212.59612 | E9: =D9/C9 -> 0.014844919 | F9: =STDEV('原始读数'!F104:F111) -> 5.4357941 | G9: =C9-B9 -> 14150.862
A10: P3 | B10: =AVERAGE('原始读数'!F200:F207) -> 157.6125 | C10: =AVERAGE('原始读数'!F208:F215) -> 12227.362 | D10: =STDEV('原始读数'!F208:F215) -> 335.17694 | E10: =D10/C10 -> 0.027412039 | F10: =STDEV('原始读数'!F200:F207) -> 3.4440166 | G10: =C10-B10 -> 12069.75
A11: 阈值用于演示复核标记；高 CV 孔组保留参与计算，并回查原始记录。
A13: P1 背景扣除后的相对活性 / %
B14: 1 | C14: 2 | D14: 3 | E14: 4 | F14: 5 | G14: 6 | H14: 7 | I14: 8 | J14: 9 | K14: 10 | L14: 11 | M14: 12
A15: A | B15: =('原始读数'!F8-$B$8)/$G$8 -> -0.00041142951 | C15: =('原始读数'!F16-$B$8)/$G$8 -> 0.95039825 | D15: =('原始读数'!F24-$B$8)/$G$8 -> 0.92497583 | E15: =('原始读数'!F32-$B$8)/$G$8 -> 1.0413124 | F15: =('原始读数'!F40-$B$8)/$G$8 -> 1.0264931 | G15: =('原始读数'!F48-$B$8)/$G$8 -> 0.91027408 | H15: =('原始读数'!F56-$B$8)/$G$8 -> 0.86395104 | I15: =('原始读数'!F64-$B$8)/$G$8 -> 0.55875654 | J15: =('原始读数'!F72-$B$8)/$G$8 -> 0.2869231 | K15: =('原始读数'!F80-$B$8)/$G$8 -> 0.11038458 | L15: =('原始读数'!F88-$B$8)/$G$8 -> 0.054892534 | M15: =('原始读数'!F96-$B$8)/$G$8 -> 0.031672236
A16: B | B16: =('原始读数'!F9-$B$8)/$G$8 -> 0.00029387822 | C16: =('原始读数'!F17-$B$8)/$G$8 -> 1.0360069 | D16: =('原始读数'!F25-$B$8)/$G$8 -> 1.0351449 | E16: =('原始读数'!F33-$B$8)/$G$8 -> 0.94455204 | F16: =('原始读数'!F41-$B$8)/$G$8 -> 1.0628713 | G16: =('原始读数'!F49-$B$8)/$G$8 -> 0.99821812 | H16: =('原始读数'!F57-$B$8)/$G$8 -> 0.80223661 | I16: =('原始读数'!F65-$B$8)/$G$8 -> 0.59597328 | J16: =('原始读数'!F73-$B$8)/$G$8 -> 0.28761274 | K16: =('原始读数'!F81-$B$8)/$G$8 -> 0.11310393 | L16: =('原始读数'!F89-$B$8)/$G$8 -> 0.053779715 | M16: =('原始读数'!F97-$B$8)/$G$8 -> 0.032643993
A17: C | B17: =('原始读数'!F10-$B$8)/$G$8 -> -5.0938892e-05 | C17: =('原始读数'!F18-$B$8)/$G$8 -> 1.0002322 | D17: =('原始读数'!F26-$B$8)/$G$8 -> 1.0131706 | E17: =('原始读数'!F34-$B$8)/$G$8 -> 0.99042839 | F17: =('原始读数'!F42-$B$8)/$G$8 -> 0.99774008 | G17: =('原始读数'!F50-$B$8)/$G$8 -> 0.94335301 | H17: =('原始读数'!F58-$B$8)/$G$8 -> 0.81870163 | I17: =('原始读数'!F66-$B$8)/$G$8 -> 0.57638924 | J17: =('原始读数'!F74-$B$8)/$G$8 -> 0.29833342 | K17: =('原始读数'!F82-$B$8)/$G$8 -> 0.1022657 | L17: =('原始读数'!F90-$B$8)/$G$8 -> 0.056154251 | M17: =('原始读数'!F98-$B$8)/$G$8 -> 0.033506036
A18: D | B18: =('原始读数'!F11-$B$8)/$G$8 -> -0.00048979704 | C18: =('原始读数'!F19-$B$8)/$G$8 -> 1.0271279 | D18: =('原始读数'!F27-$B$8)/$G$8 -> 1.0561866 | E18: =('原始读数'!F35-$B$8)/$G$8 -> 0.99957388 | F18: =('原始读数'!F43-$B$8)/$G$8 -> 0.97988012 | G18: =('原始读数'!F51-$B$8)/$G$8 -> 0.98439409 | H18: =('原始读数'!F59-$B$8)/$G$8 -> 0.86743055 | I18: =('原始读数'!F67-$B$8)/$G$8 -> 0.56731428 | J18: =('原始读数'!F75-$B$8)/$G$8 -> 0.2828715 | K18: =('原始读数'!F83-$B$8)/$G$8 -> 0.11079993 | L18: =('原始读数'!F91-$B$8)/$G$8 -> 0.05424992 | M18: =('原始读数'!F99-$B$8)/$G$8 -> 0.032017053
A19: E | B19: =('原始读数'!F12-$B$8)/$G$8 -> -0.00018416369 | C19: =('原始读数'!F20-$B$8)/$G$8 -> 0.9816669 | D19: =('原始读数'!F28-$B$8)/$G$8 -> 0.96339159 | E19: =('原始读数'!F36-$B$8)/$G$8 -> 0.98883753 | F19: =('原始读数'!F44-$B$8)/$G$8 -> 0.97281137 | G19: =('原始读数'!F52-$B$8)/$G$8 -> 0.94474012 | H19: =('原始读数'!F60-$B$8)/$G$8 -> 0.8534733 | I19: =('原始读数'!F68-$B$8)/$G$8 -> 0.56370937 | J19: =('原始读数'!F76-$B$8)/$G$8 -> 0.30426584 | K19: =('原始读数'!F84-$B$8)/$G$8 -> 0.11191275 | L19: =('原始读数'!F92-$B$8)/$G$8 -> 0.053301673 | M19: =('原始读数'!F100-$B$8)/$G$8 -> 0.031860318
A20: F | B20: =('原始读数'!F13-$B$8)/$G$8 -> 0.00052114405 | C20: =('原始读数'!F21-$B$8)/$G$8 -> 0.96637739 | D20: =('原始读数'!F29-$B$8)/$G$8 -> 0.99165876 | E20: =('原始读数'!F37-$B$8)/$G$8 -> 0.97846167 | F20: =('原始读数'!F45-$B$8)/$G$8 -> 0.95189507 | G20: =('原始读数'!F53-$B$8)/$G$8 -> 0.95818799 | H20: =('原始读数'!F61-$B$8)/$G$8 -> 0.80294975 | I20: =('原始读数'!F69-$B$8)/$G$8 -> 0.61139601 | J20: =('原始读数'!F77-$B$8)/$G$8 -> 0.27349091 | K20: =('原始读数'!F85-$B$8)/$G$8 -> 0.10764172 | L20: =('原始读数'!F93-$B$8)/$G$8 -> 0.055613515 | M20: =('原始读数'!F101-$B$8)/$G$8 -> 0.032322686
A21: G | B21: =('原始读数'!F14-$B$8)/$G$8 -> -0.000364409 | C21: =('原始读数'!F22-$B$8)/$G$8 -> 0.97875162 | D21: =('原始读数'!F30-$B$8)/$G$8 -> 0.92572816 | E21: =('原始读数'!F38-$B$8)/$G$8 -> 0.95831337 | F21: =('原始读数'!F46-$B$8)/$G$8 -> 0.92068129 | G21: =('原始读数'!F54-$B$8)/$G$8 -> 0.94059448 | H21: =('原始读数'!F62-$B$8)/$G$8 -> 0.7898467 | I21: =('原始读数'!F70-$B$8)/$G$8 -> 0.59642781 | J21: =('原始读数'!F78-$B$8)/$G$8 -> 0.29856068 | K21: =('原始读数'!F86-$B$8)/$G$8 -> 0.10906017 | L21: =('原始读数'!F94-$B$8)/$G$8 -> 0.051311138 | M21: =('原始读数'!F102-$B$8)/$G$8 -> 0.032894769
A22: H | B22: =('原始读数'!F15-$B$8)/$G$8 -> 0.00068571585 | C22: =('原始读数'!F23-$B$8)/$G$8 -> 1.0594388 | D22: =('原始读数'!F31-$B$8)/$G$8 -> 1.0062194 | E22: =('原始读数'!F39-$B$8)/$G$8 -> 0.95369753 | F22: =('原始读数'!F47-$B$8)/$G$8 -> 1.0024891 | G22: =('原始读数'!F55-$B$8)/$G$8 -> 0.94228722 | H22: =('原始读数'!F63-$B$8)/$G$8 -> 0.84660047 | I22: =('原始读数'!F71-$B$8)/$G$8 -> 0.59098127 | J22: =('原始读数'!F79-$B$8)/$G$8 -> 0.28892931 | K22: =('原始读数'!F87-$B$8)/$G$8 -> 0.11545496 | L22: =('原始读数'!F95-$B$8)/$G$8 -> 0.052627712 | M22: =('原始读数'!F103-$B$8)/$G$8 -> 0.033788159
B24: 孔位颜色按原始读数和本板对照实时计算；所有测量值均保留。
A27: P2 背景扣除后的相对活性 / %
B28: 1 | C28: 2 | D28: 3 | E28: 4 | F28: 5 | G28: 6 | H28: 7 | I28: 8 | J28: 9 | K28: 10 | L28: 11 | M28: 12
A29: A | B29: =('原始读数'!F104-$B$9)/$G$9 -> -0.00021730124 | C29: =('原始读数'!F112-$B$9)/$G$9 -> 0.99409665 | D29: =('原始读数'!F120-$B$9)/$G$9 -> 0.95750524 | E29: =('原始读数'!F128-$B$9)/$G$9 -> 0.96609836 | F29: =('原始读数'!F136-$B$9)/$G$9 -> 0.97369507 | G29: =('原始读数'!F144-$B$9)/$G$9 -> 0.90163585 | H29: =('原始读数'!F152-$B$9)/$G$9 -> 0.86046522 | I29: =('原始读数'!F160-$B$9)/$G$9 -> 0.64645 | J29: =('原始读数'!F168-$B$9)/$G$9 -> 0.30610325 | K29: =('原始读数'!F176-$B$9)/$G$9 -> 0.13188772 | L29: =('原始读数'!F184-$B$9)/$G$9 -> 0.063884799 | M29: =('原始读数'!F192-$B$9)/$G$9 -> 0.035526103
A30: B | B30: =('原始读数'!F105-$B$9)/$G$9 -> 0.00077203775 | C30: =('原始读数'!F113-$B$9)/$G$9 -> 1.0225684 | D30: =('原始读数'!F121-$B$9)/$G$9 -> 0.96912291 | E30: =('原始读数'!F129-$B$9)/$G$9 -> 1.0004284 | F30: =('原始读数'!F137-$B$9)/$G$9 -> 1.0497399 | G30: =('原始读数'!F145-$B$9)/$G$9 -> 0.93188136 | H30: =('原始读数'!F153-$B$9)/$G$9 -> 0.87001941 | I30: =('原始读数'!F161-$B$9)/$G$9 -> 0.60508856 | J30: =('原始读数'!F169-$B$9)/$G$9 -> 0.31314169 | K30: =('原始读数'!F177-$B$9)/$G$9 -> 0.12465141 | L30: =('原始读数'!F185-$B$9)/$G$9 -> 0.061637586 | M30: =('原始读数'!F193-$B$9)/$G$9 -> 0.03664971
A31: C | B31: =('原始读数'!F106-$B$9)/$G$9 -> -0.0003798355 | C31: =('原始读数'!F114-$B$9)/$G$9 -> 1.003559 | D31: =('原始读数'!F122-$B$9)/$G$9 -> 1.0461005 | E31: =('原始读数'!F130-$B$9)/$G$9 -> 1.044136 | F31: =('原始读数'!F138-$B$9)/$G$9 -> 0.98031657 | G31: =('原始读数'!F146-$B$9)/$G$9 -> 0.99882428 | H31: =('原始读数'!F154-$B$9)/$G$9 -> 0.88819498 | I31: =('原始读数'!F162-$B$9)/$G$9 -> 1.0107529 | J31: =('原始读数'!F170-$B$9)/$G$9 -> 0.31049874 | K31: =('原始读数'!F178-$B$9)/$G$9 -> 0.12696929 | L31: =('原始读数'!F186-$B$9)/$G$9 -> 0.066117878 | M31: =('原始读数'!F194-$B$9)/$G$9 -> 0.036812244
A32: D | B32: =('原始读数'!F107-$B$9)/$G$9 -> 0.00017136765 | C32: =('原始读数'!F115-$B$9)/$G$9 -> 0.97832376 | D32: =('原始读数'!F123-$B$9)/$G$9 -> 0.91570567 | E32: =('原始读数'!F131-$B$9)/$G$9 -> 1.0656965 | F32: =('原始读数'!F139-$B$9)/$G$9 -> 1.0088166 | G32: =('原始读数'!F147-$B$9)/$G$9 -> 0.9444389 | H32: =('原始读数'!F155-$B$9)/$G$9 -> 0.8638007 | I32: =('原始读数'!F163-$B$9)/$G$9 -> 0.62353973 | J32: =('原始读数'!F171-$B$9)/$G$9 -> 0.30754486 | K32: =('原始读数'!F179-$B$9)/$G$9 -> 0.13209266 | L32: =('原始读数'!F187-$B$9)/$G$9 -> 0.063015594 | M32: =('原始读数'!F195-$B$9)/$G$9 -> 0.036875844
A33: E | B33: =('原始读数'!F108-$B$9)/$G$9 -> 5.1233626e-05 | C33: =('原始读数'!F116-$B$9)/$G$9 -> 1.001651 | D33: =('原始读数'!F124-$B$9)/$G$9 -> 1.0141096 | E33: =('原始读数'!F132-$B$9)/$G$9 -> 0.99544639 | F33: =('原始读数'!F140-$B$9)/$G$9 -> 0.95470682 | G33: =('原始读数'!F148-$B$9)/$G$9 -> 0.92998042 | H33: =('原始读数'!F156-$B$9)/$G$9 -> 0.86476178 | I33: =('原始读数'!F164-$B$9)/$G$9 -> 0.69025651 | J33: =('原始读数'!F172-$B$9)/$G$9 -> 0.33250447 | K33: =('原始读数'!F180-$B$9)/$G$9 -> 0.12373981 | L33: =('原始读数'!F188-$B$9)/$G$9 -> 0.065178006 | M33: =('原始读数'!F196-$B$9)/$G$9 -> 0.039561193
A34: F | B34: =('原始读数'!F109-$B$9)/$G$9 -> -0.00045050258 | C34: =('原始读数'!F117-$B$9)/$G$9 -> 1.0188867 | D34: =('原始读数'!F125-$B$9)/$G$9 -> 0.97847216 | E34: =('原始读数'!F133-$B$9)/$G$9 -> 0.99526972 | F34: =('原始读数'!F141-$B$9)/$G$9 -> 0.9626498 | G34: =('原始读数'!F149-$B$9)/$G$9 -> 0.98688154 | H34: =('原始读数'!F157-$B$9)/$G$9 -> 0.80188222 | I34: =('原始读数'!F165-$B$9)/$G$9 -> 0.64799054 | J34: =('原始读数'!F173-$B$9)/$G$9 -> 0.33083672 | K34: =('原始读数'!F181-$B$9)/$G$9 -> 0.12719543 | L34: =('原始读数'!F189-$B$9)/$G$9 -> 0.061559852 | M34: =('原始读数'!F197-$B$9)/$G$9 -> 0.03675571
A35: G | B35: =('原始读数'!F110-$B$9)/$G$9 -> 9.3633869e-05 | C35: =('原始读数'!F118-$B$9)/$G$9 -> 0.98804048 | D35: =('原始读数'!F126-$B$9)/$G$9 -> 0.99942495 | E35: =('原始读数'!F134-$B$9)/$G$9 -> 0.99194837 | F35: =('原始读数'!F142-$B$9)/$G$9 -> 0.98868355 | G35: =('原始读数'!F150-$B$9)/$G$9 -> 0.9205393 | H35: =('原始读数'!F158-$B$9)/$G$9 -> 0.8165103 | I35: =('原始读数'!F166-$B$9)/$G$9 -> 0.64505079 | J35: =('原始读数'!F174-$B$9)/$G$9 -> 0.331925 | K35: =('原始读数'!F182-$B$9)/$G$9 -> 0.12376807 | L35: =('原始读数'!F190-$B$9)/$G$9 -> 0.061022782 | M35: =('原始读数'!F198-$B$9)/$G$9 -> 0.036020773
A36: H | B36: =('原始读数'!F111-$B$9)/$G$9 -> -4.0633566e-05 | C36: =('原始读数'!F119-$B$9)/$G$9 -> 0.99287411 | D36: =('原始读数'!F127-$B$9)/$G$9 -> 0.98901569 | E36: =('原始读数'!F135-$B$9)/$G$9 -> 1.0098483 | F36: =('原始读数'!F143-$B$9)/$G$9 -> 0.96998505 | G36: =('原始读数'!F151-$B$9)/$G$9 -> 0.93422044 | H36: =('原始读数'!F159-$B$9)/$G$9 -> 0.8579424 | I36: =('原始读数'!F167-$B$9)/$G$9 -> 0.65432231 | J36: =('原始读数'!F175-$B$9)/$G$9 -> 0.31654078 | K36: =('原始读数'!F183-$B$9)/$G$9 -> 0.1221286 | L36: =('原始读数'!F191-$B$9)/$G$9 -> 0.062754125 | M36: =('原始读数'!F199-$B$9)/$G$9 -> 0.036430642
B38: 孔位颜色按原始读数和本板对照实时计算；所有测量值均保留。
A41: P3 背景扣除后的相对活性 / %
B42: 1 | C42: 2 | D42: 3 | E42: 4 | F42: 5 | G42: 6 | H42: 7 | I42: 8 | J42: 9 | K42: 10 | L42: 11 | M42: 12
A43: A | B43: =('原始读数'!F200-$B$10)/$G$10 -> 0.00024751963 | C43: =('原始读数'!F208-$B$10)/$G$10 -> 1.0243367 | D43: =('原始读数'!F216-$B$10)/$G$10 -> 0.95998571 | E43: =('原始读数'!F224-$B$10)/$G$10 -> 0.96760807 | F43: =('原始读数'!F232-$B$10)/$G$10 -> 0.99882661 | G43: =('原始读数'!F240-$B$10)/$G$10 -> 0.98773276 | H43: =('原始读数'!F248-$B$10)/$G$10 -> 0.84118457 | I43: =('原始读数'!F256-$B$10)/$G$10 -> 0.58612544 | J43: =('原始读数'!F264-$B$10)/$G$10 -> 0.30412291 | K43: =('原始读数'!F272-$B$10)/$G$10 -> 0.12531225 | L43: =('原始读数'!F280-$B$10)/$G$10 -> 0.057498084 | M43: =('原始读数'!F288-$B$10)/$G$10 -> 0.033951615
A44: B | B44: =('原始读数'!F201-$B$10)/$G$10 -> -0.00051471654 | C44: =('原始读数'!F209-$B$10)/$G$10 -> 0.96530479 | D44: =('原始读数'!F217-$B$10)/$G$10 -> 0.9311533 | E44: =('原始读数'!F225-$B$10)/$G$10 -> 0.92838605 | F44: =('原始读数'!F233-$B$10)/$G$10 -> 1.0101276 | G44: =('原始读数'!F241-$B$10)/$G$10 -> 0.93239607 | H44: =('原始读数'!F249-$B$10)/$G$10 -> 0.78914538 | I44: =('原始读数'!F257-$B$10)/$G$10 -> 0.60200812 | J44: =('原始读数'!F265-$B$10)/$G$10 -> 0.30706415 | K44: =('原始读数'!F273-$B$10)/$G$10 -> 0.10775596 | L44: =('原始读数'!F281-$B$10)/$G$10 -> 0.055385364 | M44: =('原始读数'!F289-$B$10)/$G$10 -> 0.034142174
A45: C | B45: =('原始读数'!F202-$B$10)/$G$10 -> 1.5534705e-05 | C45: =('原始读数'!F210-$B$10)/$G$10 -> 1.0036486 | D45: =('原始读数'!F218-$B$10)/$G$10 -> 0.95646451 | E45: =('原始读数'!F226-$B$10)/$G$10 -> 0.94318337 | F45: =('原始读数'!F234-$B$10)/$G$10 -> 0.96885913 | G45: =('原始读数'!F242-$B$10)/$G$10 -> 0.9416589 | H45: =('原始读数'!F250-$B$10)/$G$10 -> 0.82120901 | I45: =('原始读数'!F258-$B$10)/$G$10 -> 0.5547909 | J45: =('原始读数'!F266-$B$10)/$G$10 -> 0.28626836 | K45: =('原始读数'!F274-$B$10)/$G$10 -> 0.11183227 | L45: =('原始读数'!F282-$B$10)/$G$10 -> 0.059337393 | M45: =('原始读数'!F290-$B$10)/$G$10 -> 0.033529071
A46: D | B46: =('原始读数'!F203-$B$10)/$G$10 -> 0.00042150832 | C46: =('原始读数'!F211-$B$10)/$G$10 -> 1.0148419 | D46: =('原始读数'!F219-$B$10)/$G$10 -> 0.95293502 | E46: =('原始读数'!F227-$B$10)/$G$10 -> 0.96924853 | F46: =('原始读数'!F235-$B$10)/$G$10 -> 0.93563558 | G46: =('原始读数'!F243-$B$10)/$G$10 -> 0.99059943 | H46: =('原始读数'!F251-$B$10)/$G$10 -> 0.79833364 | I46: =('原始读数'!F259-$B$10)/$G$10 -> 0.584021 | J46: =('原始读数'!F267-$B$10)/$G$10 -> 0.30563081 | K46: =('原始读数'!F275-$B$10)/$G$10 -> 0.11097889 | L46: =('原始读数'!F283-$B$10)/$G$10 -> 0.057324095 | M46: =('原始读数'!F291-$B$10)/$G$10 -> 0.035235817
A47: E | B47: =('原始读数'!F204-$B$10)/$G$10 -> -0.00014188363 | C47: =('原始读数'!F212-$B$10)/$G$10 -> 1.03954 | D47: =('原始读数'!F220-$B$10)/$G$10 -> 0.9957611 | E47: =('原始读数'!F228-$B$10)/$G$10 -> 1.0095062 | F47: =('原始读数'!F236-$B$10)/$G$10 -> 0.96462541 | G47: =('原始读数'!F244-$B$10)/$G$10 -> 0.87488867 | H47: =('原始读数'!F252-$B$10)/$G$10 -> 0.85650386 | I47: =('原始读数'!F260-$B$10)/$G$10 -> 0.61523955 | J47: =('原始读数'!F268-$B$10)/$G$10 -> 0.30713043 | K47: =('原始读数'!F276-$B$10)/$G$10 -> 0.11070548 | L47: =('原始读数'!F284-$B$10)/$G$10 -> 0.056909837 | M47: =('原始读数'!F292-$B$10)/$G$10 -> 0.034241596
A48: F | B48: =('原始读数'!F205-$B$10)/$G$10 -> 0.00016466787 | C48: =('原始读数'!F213-$B$10)/$G$10 -> 0.99222333 | D48: =('原始读数'!F221-$B$10)/$G$10 -> 0.98120404 | E48: =('原始读数'!F229-$B$10)/$G$10 -> 0.96168417 | F48: =('原始读数'!F237-$B$10)/$G$10 -> 0.96478282 | G48: =('原始读数'!F245-$B$10)/$G$10 -> 0.91660453 | H48: =('原始读数'!F253-$B$10)/$G$10 -> 0.81085254 | I48: =('原始读数'!F261-$B$10)/$G$10 -> 0.55018435 | J48: =('原始读数'!F269-$B$10)/$G$10 -> 0.30423062 | K48: =('原始读数'!F277-$B$10)/$G$10 -> 0.11339816 | L48: =('原始读数'!F285-$B$10)/$G$10 -> 0.056727563 | M48: =('原始读数'!F293-$B$10)/$G$10 -> 0.032899397
A49: G | B49: =('原始读数'!F206-$B$10)/$G$10 -> -0.00010045776 | C49: =('原始读数'!F214-$B$10)/$G$10 -> 1.0018341 | D49: =('原始读数'!F222-$B$10)/$G$10 -> 1.0160184 | E49: =('原始读数'!F230-$B$10)/$G$10 -> 0.94123636 | F49: =('原始读数'!F238-$B$10)/$G$10 -> 0.94542865 | G49: =('原始读数'!F246-$B$10)/$G$10 -> 0.98165144 | H49: =('原始读数'!F254-$B$10)/$G$10 -> 0.86077073 | I49: =('原始读数'!F262-$B$10)/$G$10 -> 0.61020216 | J49: =('原始读数'!F270-$B$10)/$G$10 -> 0.28511672 | K49: =('原始读数'!F278-$B$10)/$G$10 -> 0.11551088 | L49: =('原始读数'!F286-$B$10)/$G$10 -> 0.057307525 | M49: =('原始读数'!F294-$B$10)/$G$10 -> 0.031822324
A50: H | B50: =('原始读数'!F207-$B$10)/$G$10 -> -9.217258e-05 | C50: =('原始读数'!F215-$B$10)/$G$10 -> 0.95827068 | D50: =('原始读数'!F223-$B$10)/$G$10 -> 0.97194122 | E50: =('原始读数'!F231-$B$10)/$G$10 -> 0.98499865 | F50: =('原始读数'!F239-$B$10)/$G$10 -> 0.96374718 | G50: =('原始读数'!F247-$B$10)/$G$10 -> 0.92950455 | H50: =('原始读数'!F255-$B$10)/$G$10 -> 0.85700097 | I50: =('原始读数'!F263-$B$10)/$G$10 -> 0.632423 | J50: =('原始读数'!F271-$B$10)/$G$10 -> 0.28746142 | K50: =('原始读数'!F279-$B$10)/$G$10 -> 0.10945442 | L50: =('原始读数'!F287-$B$10)/$G$10 -> 0.058044906 | M50: =('原始读数'!F295-$B$10)/$G$10 -> 0.033504215
B52: 孔位颜色按原始读数和本板对照实时计算；所有测量值均保留。

Sheet 原始读数
A2: 原始荧光读数
A3: 288 个模拟孔位全部保留；此预览展示前 39 条原始读数
A4: 模拟方法：固定种子 41865；浓度响应叠加批次差异和测量噪声，记录中保留一处偏差。
A7: 批次 | B7: 孔位 | C7: 类型 | D7: 浓度µM | E7: 技术重复 | F7: 荧光RFU | G7: 记录
A8: P1 | B8: A01 | C8: 空白 | E8: 1 | F8: 142.1
A9: P1 | B9: B01 | C9: 空白 | E9: 2 | F9: 151.1
A10: P1 | B10: C01 | C10: 空白 | E10: 3 | F10: 146.7
A11: P1 | B11: D01 | C11: 空白 | E11: 4 | F11: 141.1
A12: P1 | B12: E01 | C12: 空白 | E12: 5 | F12: 145
A13: P1 | B13: F01 | C13: 空白 | E13: 6 | F13: 154
A14: P1 | B14: G01 | C14: 空白 | E14: 7 | F14: 142.7
A15: P1 | B15: H01 | C15: 空白 | E15: 8 | F15: 156.1
A16: P1 | B16: A02 | C16: 溶剂对照 | E16: 1 | F16: 12274.8
A17: P1 | B17: B02 | C17: 溶剂对照 | E17: 2 | F17: 13367.2
A18: P1 | B18: C02 | C18: 溶剂对照 | E18: 3 | F18: 12910.7
A19: P1 | B19: D02 | C19: 溶剂对照 | E19: 4 | F19: 13253.9
... A23: P1 | B23: H02 | C23: 溶剂对照 | E23: 8 | F23: 13666.2
A24: P1 | B24: A03 | C24: 样品 | D24: 0.01 | E24: 1 | F24: 11950.4
A25: P1 | B25: B03 | C25: 样品 | D25: 0.01 | E25: 2 | F25: 13356.2
A26: P1 | B26: C03 | C26: 样品 | D26: 0.01 | E26: 3 | F26: 13075.8
A27: P1 | B27: D03 | C27: 样品 | D27: 0.01 | E27: 4 | F27: 13624.7
A28: P1 | B28: E03 | C28: 样品 | D28: 0.01 | E28: 5 | F28: 12440.6
A29: P1 | B29: F03 | C29: 样品 | D29: 0.01 | E29: 6 | F29: 12801.3
A30: P1 | B30: G03 | C30: 样品 | D30: 0.01 | E30: 7 | F30: 11960
A31: P1 | B31: H03 | C31: 样品 | D31: 0.01 | E31: 8 | F31: 12987.1
A32: P1 | B32: A04 | C32: 样品 | D32: 0.03 | E32: 1 | F32: 13434.9
A33: P1 | B33: B04 | C33: 样品 | D33: 0.03 | E33: 2 | F33: 12200.2
A34: P1 | B34: C04 | C34: 样品 | D34: 0.03 | E34: 3 | F34: 12785.6
A35: P1 | B35: D04 | C35: 样品 | D35: 0.03 | E35: 4 | F35: 12902.3
... A103: P1 | B103: H12 | C103: 样品 | D103: 100 | E103: 8 | F103: 578.5
A104: P2 | B104: A01 | C104: 空白 | E104: 1 | F104: 167.2
A105: P2 | B105: B01 | C105: 空白 | E105: 2 | F105: 181.2
A106: P2 | B106: C01 | C106: 空白 | E106: 3 | F106: 164.9
A107: P2 | B107: D01 | C107: 空白 | E107: 4 | F107: 172.7
A108: P2 | B108: E01 | C108: 空白 | E108: 5 | F108: 171
A109: P2 | B109: F01 | C109: 空白 | E109: 6 | F109: 163.9
A110: P2 | B110: G01 | C110: 空白 | E110: 7 | F110: 171.6
A111: P2 | B111: H01 | C111: 空白 | E111: 8 | F111: 169.7
A112: P2 | B112: A02 | C112: 溶剂对照 | E112: 1 | F112: 14237.6
A113: P2 | B113: B02 | C113: 溶剂对照 | E113: 2 | F113: 14640.5
...
